{"primaryContentSections":[{"kind":"declarations","declarations":[{"tokens":[{"kind":"keyword","text":"let"},{"kind":"text","text":" "},{"kind":"identifier","text":"error"},{"kind":"text","text":": "},{"kind":"typeIdentifier","identifier":"doc:\/\/DigiMeSDK\/documentation\/DigiMeSDK\/SyncError","preciseIdentifier":"s:9DigiMeSDK9SyncErrorV","text":"SyncError"},{"kind":"text","text":"?"}],"languages":["swift"],"platforms":["iOS"]}]}],"schemaVersion":{"major":0,"minor":3,"patch":0},"sections":[],"variants":[{"paths":["\/documentation\/digimesdk\/syncaccount\/error"],"traits":[{"interfaceLanguage":"swift"}]}],"identifier":{"url":"doc:\/\/DigiMeSDK\/documentation\/DigiMeSDK\/SyncAccount\/error","interfaceLanguage":"swift"},"abstract":[{"type":"text","text":"An error giving details of the reason synchronization failed."},{"type":"text","text":" "},{"type":"text","text":"Only available for ‘partial’ synchronization state"}],"kind":"symbol","metadata":{"fragments":[{"kind":"keyword","text":"let"},{"kind":"text","text":" "},{"kind":"identifier","text":"error"},{"kind":"text","text":": "},{"kind":"typeIdentifier","text":"SyncError","preciseIdentifier":"s:9DigiMeSDK9SyncErrorV"},{"kind":"text","text":"?"}],"title":"error","roleHeading":"Instance Property","role":"symbol","symbolKind":"property","externalID":"s:9DigiMeSDK11SyncAccountV5errorAA0D5ErrorVSgvp","modules":[{"name":"DigiMeSDK"}]},"hierarchy":{"paths":[["doc:\/\/DigiMeSDK\/documentation\/DigiMeSDK","doc:\/\/DigiMeSDK\/documentation\/DigiMeSDK\/SyncAccount"]]},"references":{"doc://DigiMeSDK/documentation/DigiMeSDK/SyncError":{"role":"symbol","title":"SyncError","fragments":[{"kind":"keyword","text":"struct"},{"kind":"text","text":" "},{"kind":"identifier","text":"SyncError"}],"abstract":[{"type":"text","text":"Reason why connecting to source or importing data from source into user’s library failed"}],"identifier":"doc:\/\/DigiMeSDK\/documentation\/DigiMeSDK\/SyncError","kind":"symbol","type":"topic","navigatorTitle":[{"kind":"identifier","text":"SyncError"}],"url":"\/documentation\/digimesdk\/syncerror"},"doc://DigiMeSDK/documentation/DigiMeSDK/SyncAccount":{"role":"symbol","title":"SyncAccount","fragments":[{"kind":"keyword","text":"struct"},{"kind":"text","text":" "},{"kind":"identifier","text":"SyncAccount"}],"abstract":[{"type":"text","text":"Details of a source being synchronized"}],"identifier":"doc:\/\/DigiMeSDK\/documentation\/DigiMeSDK\/SyncAccount","kind":"symbol","type":"topic","navigatorTitle":[{"kind":"identifier","text":"SyncAccount"}],"url":"\/documentation\/digimesdk\/syncaccount"},"doc://DigiMeSDK/documentation/DigiMeSDK":{"role":"collection","title":"DigiMeSDK","abstract":[{"type":"text","text":"Digi.me - The Private Sharing Platform"}],"identifier":"doc:\/\/DigiMeSDK\/documentation\/DigiMeSDK","kind":"symbol","type":"topic","url":"\/documentation\/digimesdk"},"doc://DigiMeSDK/documentation/DigiMeSDK/SyncAccount/error":{"role":"symbol","title":"error","fragments":[{"kind":"keyword","text":"let"},{"kind":"text","text":" "},{"kind":"identifier","text":"error"},{"kind":"text","text":": "},{"kind":"typeIdentifier","text":"SyncError","preciseIdentifier":"s:9DigiMeSDK9SyncErrorV"},{"kind":"text","text":"?"}],"abstract":[{"type":"text","text":"An error giving details of the reason synchronization failed."},{"type":"text","text":" "},{"type":"text","text":"Only available for ‘partial’ synchronization state"}],"identifier":"doc:\/\/DigiMeSDK\/documentation\/DigiMeSDK\/SyncAccount\/error","kind":"symbol","type":"topic","url":"\/documentation\/digimesdk\/syncaccount\/error"}}}